<!DOCTYPE HTML PUBLIC "-//W3C//DTD HTML 4.01 Transitional//EN" "http://www.w3.org/TR/html4/loose.dtd">
<html>
	<head>	
		<meta http-equiv="Content-Type" content="text/html; charset=iso-8859-1">
		<link href="resources/web/styles.css" rel="stylesheet" type="text/css">
		<link href="styles.css" rel="stylesheet" type="text/css">
		
		<title>Dealing with Exceptional Situations</title>					
	</head>	
	
	<body>
		<div class="page_header">
			<!-- For local testing -->
			<!--a href="http://web.cs.toronto.edu/"><img src="bluescreen.jpg" alt="University of Toronto - Computer Science - Image" ></a-->
			
			<!-- For web version -->
			<a href="http://web.cs.toronto.edu/"><img src="https://d3c33hcgiwev3.cloudfront.net/imageAssetProxy.v1/_effbbd4e792a0bbfa32f5b33444045d6_bluescreen.jpg?expiry=1489795200000&hmac=yVxwAaLMzbeJe1no7Efm_o9mRmy_tW6Xtq9GXhm_V5c" alt="University of Toronto - Computer Science - Image" ></a>			
			<hr>
		</div>
		
		<h1>Dealing with Exceptional Situations</h1> 
		<div class="indent">
			So far, we have assumed input to functions is valid.  In this lecture, we show you what to do when input is invalid (or preconditions are not met).<br>			
			<h2>Errors</h2>
			<div class="indent">
				We have all seen errors!<br>				
				<h3>Division by 0</h3>
				<div class="indent">
					Calling <code>1 / 0</code> results in the following:
					<div class="indent">
						<table class="bordered"><tr><td><span class="red">
<pre>
Traceback (most recent call last):
  File "&ltpyshell#0&gt", line 1, in <module>
    1 / 0
ZeroDivisionError: division by zero
</pre>
						</span></td></tr></table>
					</div>	
				</div>
				<h3>Value Error </h3>
				<div class="indent">
					Calling <code>'abc'.index('q')</code> or <code>int('moogah')</code> results in the following:
					<div class="indent">
						<table class="bordered"><tr><td><span class="red">			
<pre>
Traceback (most recent call last):
  File "&ltpyshell#0&gt", line 1, in <module>
    'abc'.index('q')
ValueError: substring not found
</pre>
						</span></td></tr></table>					
						<br>
						and<br>
						<br>					
						<table class="bordered"><tr><td><span class="red">
<pre>
Traceback (most recent call last):
  File "&ltpyshell#0&gt", line 1, in <module>
    'int('moogah')
ValueError: invalid literal for int() with base 10: 'moogah'
</pre>
						</span></td></tr></table>
					</div>
					<br>
					Both are value errors, but with very different details.
				</div>
			<br>				
			You can call for help on errors (i.e. <code>help(ValueError)</code>)<br>
			<br>
			Errors happen when the code tries to make a function do something it wasn't designed to do.<br>
			You can use exceptions when you encounter a situation that is not part of the normal flow of execution.<br>			
			</div>
		<h2>Exception Handling</h2>
		<div class="indent">
			Python has an exception handling statements:<br>
			<br>
			The <code>try</code> statement (simple form):
			<div class="indent">
				<table class="bordered"><tr><td>
<pre>
try:
    statements
except:
    statements
</pre>
				</td></tr></table>
			</div>
			<br>
			If a statement in the <code>try</code> block raises an exception, the remaining statements in the block are not executed.<br>
			<br>			
			With the <code>except</code> clause, we can specify the exception we would like to catch.<br>
			<br>
			For example,<br>
			<br>
			<div class="indent">
<pre>
try:
    1 / 0
except ZeroDivisionError:
    print("Divided by zero.")
</pre>							
			</div>
			<br>
			This code still catches the divide by zero error; however,<br>
			<br>	
			<div class="indent">
<pre>
try:
    1 / 0
except ValueError:
    print("Divided by zero.")
</pre>
			</div>
			<br>
			will not catch the error.<br>
			<br>
			Python can handle both errors separately.<br>
			<br>
			<code>try</code> statement (specifying exception types):
			<div class="indent">
				<table class="bordered"><tr><td>
<pre>
try:
    statements
except ExceptionType:
    statements
except ExceptionType:
    statements
</pre>		
				</td></tr></table>
			</div>
			<br>
			With multiple <code>except</code> clauses, Python executes the block of the first matching exception type.<br>
			<br>
			<b>Warning:</b> If you want to handle two kinds of exceptions, and one is a subclass of the other, catch the subclass first.<br>
			<br>
			Every exception is an object and can be assigned a variable name.  This variable can be used like any other variable.<br>			
		</div>
		<h2>Raise Errors</h2>
		<div class="indent">
			We can cause an exception to happen by using the <code>raise</code> statement.<br>
			<br>
			For example:
			<div class="indent">
				<table class="bordered"><tr><td>
					<code>raise ValueError("Oops. Bad value. No cookie.")</code>
				</td></tr></table>
			</div>
			<br>
			results in:
			<div class="indent">
				<table class="bordered"><tr><td><span class="red">
<pre>
Traceback (most recent call last):
  File "&ltpyshell#0&gt", line 1, in <module>
    raise ValueError("Oops. Bad value. No cookie.")
ValueError: Oops. Bad value. No cookie.
</pre>			
				</span></td></tr></table>
			</div>
			<h3>Example Program</h3>
			<div class="indent">
				<table class="bordered"><tr><td>
<pre>
def raise_an_exception(v):
    raise ValueError("{} is not a valid value.".format(v))

def main():
    raise_an_exception(3)

if __name__ == '__main__':
    try:
        main()
    except ValueError as ve:
        print(ve)
</pre>
				</td></tr></table>
			</div>
		</div>
		<h2>Assertion</h2>
		<div class="indent">			
			Programmers often use the <code>assert</code> statement to ensure that preconditions are met.<br>
			<br>
			For example:
			<div class="indent">
				<table class="bordered"><tr><td>
<pre>
def every_nth(L, n=1):
    """ (list, int) -> list

    Precondition: 0 <= n < len(L)

    Return a list containing every nth item of L,
    starting at index 0.
	
    >>> every_nth([1, 2, 3, 4, 5, 6], n=2)
    [1, 3, 5]
    >>> every_nth([1, 2, 3, 4, 5, 6], 3)
    [1, 4]
    >>> every_nth([1, 2, 3, 4, 5, 6])
    [1, 2, 3, 4, 5, 6]
    """

    assert 0 <= n < len(L), '{} is out of range.'.format(n)
	
    result = []

    for i in range(0, len(L), n):
        result.append(L[i])

    return result

if __name__ == '__main__':
    import doctest
    doctest.testmod()
</pre>
				</td></tr></table>
			</div>
			<br>
			This program runs without errors if the preconditions are met, but raises an error if the conditions are not met.<br>			
		</div>
		<h2>Tips</h2>
		<div class="indent">
			Tips for when and how to use exceptions:
			<ul>
				<li>Exceptions should <b>not</b> be used as part of the normal flow of a program.  They are for exceptional situations.
				<li>Only catch exceptions that you know how to handle.
				<li>"Throw low, catch high."
				<li>Use an <code>assert</code> statement to verify that preconditions are met.
			</ul>
		</div>
		<div class="page_footer">
			<hr>
			<center>
				Jennifer Campbell &bull; Paul Gries<br>
				University of Toronto
			</center>
			<hr>
		</div>
	</body>	
</html>
